Workbook
Name 图片: INDEX(Sheet1!$H:$H,MATCH(Sheet1!$K$1,Sheet1!$D:$D,0))

Sheet EXCEL课件
A9: 一、 | B9: 回顾Vlookup函数
B11: 1、Vlookup函数语法
C12: VLOOKUP(lookup_value,table_array,col_index_num,[range_lookup])
A16: 二、 | B16: Match与Index函数
B18: 1、函数语法
C19: MATCH(lookup_value,lookup_array,[match_type])
C20: INDEX(array,row_num,[column_num])
B23: 2、Match+Index与Vlookup函数比较
B26: 3、使用Match与Vlookup函数嵌套返回多列结果
B29: 4、认识column函数

Sheet 数据源
A1: 客户ID | B1: 公司名称 | C1: 联系人姓名 | D1: 联系人头衔 | E1: 地址 | F1: 城市 | G1: 地区 | H1: 邮政编码 | I1: 国家 | J1: 电话 | K1: 传真
A2: AABBCCD | B2: 三川实业有限公司 | C2: 刘小姐 | D2: 销售代表 | E2: 大崇明路 50 号 | F2: 天津 | G2: 华北 | H2: 343567 | I2: 中国 | J2: (030) 30074321 | K2: (030) 30765452
A3: ANATR | B3: 东南实业 | C3: 王先生 | D3: 物主 | E3: 承德西路 80 号 | F3: 天津 | G3: 华北 | H3: 234575 | I3: 中国 | J3: (030) 35554729 | K3: (030) 35553744
A4: ANTON | B4: 坦森行贸易 | C4: 王炫皓 | D4: 物主 | E4: 黄台北路 780 号 | F4: 石家庄 | G4: 华北 | H4: 985060 | I4: 中国 | J4: (0321) 5553932
A5: AROUT | B5: 国顶有限公司 | C5: 方先生 | D5: 销售代表 | E5: 天府东街 30 号 | F5: 深圳 | G5: 华南 | H5: 890879 | I5: 中国 | J5: (0571) 45557788 | K5: (0571) 45556750
A6: BERGS | B6: 通恒机械 | C6: 黄小姐 | D6: 采购员 | E6: 东园西甲 30 号 | F6: 南京 | G6: 华东 | H6: 798089 | I6: 中国 | J6: (0921) 9123465 | K6: (0921) 55123467
A7: BLAUS | B7: 森通 | C7: 王先生 | D7: 销售代表 | E7: 常保阁东 80 号 | F7: 天津 | G7: 华北 | H7: 787045 | I7: 中国 | J7: (030) 30058460 | K7: (030) 33008924
A8: BLONP | B8: 国皓 | C8: 黄雅玲 | D8: 市场经理 | E8: 广发北路 10 号 | F8: 大连 | G8: 东北 | H8: 565479 | I8: 中国 | J8: (0671) 88601531 | K8: (0671) 88601532
A9: BOLID | B9: 迈多贸易 | C9: 陈先生 | D9: 物主 | E9: 临翠大街 80 号 | F9: 西安 | G9: 西北 | H9: 907987 | I9: 中国 | J9: (091) 85552282 | K9: (091) 85559199
A10: BONAP | B10: 祥通 | C10: 刘先生 | D10: 物主 | E10: 花园东街 90 号 | F10: 重庆 | G10: 西南 | H10: 567690 | I10: 中国 | J10: (078) 91244540 | K10: (078) 91244541
A11: BOTTM | B11: 广通 | C11: 王先生 | D11: 结算经理 | E11: 平谷嘉石大街 38 号 | F11: 重庆 | G11: 西南 | H11: 808059 | I11: 中国 | J11: (078) 95554729 | K11: (078) 95553745
A12: BSBEV | B12: 光明杂志 | C12: 谢丽秋 | D12: 销售代表 | E12: 黄石路 50 号 | F12: 深圳 | G12: 华南 | H12: 760908 | I12: 中国 | J12: (0571) 45551212
A13: CACTU | B13: 威航货运有限公司 | C13: 刘先生 | D13: 销售代理 | E13: 经七纬二路 13 号 | F13: 大连 | G13: 东北 | H13: 120412 | I13: 中国 | J13: (061) 11355555 | K13: (061) 11354892
A14: CENTC | B14: 三捷实业 | C14: 王先生 | D14: 市场经理 | E14: 英雄山路 84 号 | F14: 大连 | G14: 东北 | H14: 130083 | I14: 中国 | J14: (061) 15553392 | K14: (061) 15557293
A15: CHOPS | B15: 浩天旅行社 | C15: 方先生 | D15: 物主 | E15: 白广路 314 号 | F15: 天津 | G15: 华北 | H15: 234254 | I15: 中国 | J15: (030) 30076545
A16: COMMI | B16: 同恒 | C16: 刘先生 | D16: 销售员 | E16: 七一路 37 号 | F16: 天津 | G16: 华北 | H16: 453466 | I16: 中国 | J16: (030) 35557647
A17: CONSH | B17: 万海 | C17: 林小姐 | D17: 销售代表 | E17: 劳动路 23 号 | F17: 厦门 | G17: 华南 | H17: 353467 | I17: 中国 | J17: (071) 45552282 | K17: (071) 45559199
A18: DRACD | B18: 世邦 | C18: 黎先生 | D18: 采购员 | E18: 光明东路 395 号 | F18: 海口 | G18: 华南 | H18: 454748 | I18: 中国 | J18: (0241) 10391231 | K18: (0241) 10594282
A19: DUMON | B19: 迈策船舶 | C19: 王俊元 | D19: 物主 | E19: 沉香街 329 号 | F19: 常州 | G19: 华东 | H19: 565474 | I19: 中国 | J19: (056) 40678888 | K19: (056) 40678989
A20: EASTC | B20: 中通 | C20: 林小姐 | D20: 销售代理 | E20: 光复北路 895 号 | F20: 天津 | G20: 华北 | H20: 809784 | I20: 中国 | J20: (030) 35550297 | K20: (030) 35553373
A21: ERNSH | B21: 正人资源 | C21: 谢小姐 | D21: 销售经理 | E21: 临江东街 62 号 | F21: 深圳 | G21: 华南 | H21: 906853 | I21: 中国 | J21: (0571) 76753425 | K21: (0571) 76753426
A22: FAMIA | B22: 红阳事业 | C22: 王先生 | D22: 市场助理 | E22: 外滩西路 238 号 | F22: 深圳 | G22: 华南 | H22: 687759 | I22: 中国 | J22: (0571) 75559857
A23: FISSA | B23: 嘉元实业 | C23: 刘小姐 | D23: 结算经理 | E23: 东湖大街 28 号 | F23: 天津 | G23: 华北 | H23: 458965 | I23: 中国 | J23: (091) 25559444 | K23: (091) 25555593
A24: FOLIG | B24: 嘉业 | C24: 刘先生 | D24: 助理销售代理 | E24: 经三纬二路 8 号 | F24: 石家庄 | G24: 华北 | H24: 576906 | I24: 中国 | J24: (0321) 20161016 | K24: (0321) 20161017
A25: FOLKO | B25: 五洲信托 | C25: 苏先生 | D25: 物主 | E25: 沿江北路 942 号 | F25: 南京 | G25: 华东 | H25: 876060 | I25: 中国 | J25: (087) 69534671
A26: FRANK | B26: 友恒信托 | C26: 余小姐 | D26: 市场经理 | E26: 经二路 9 号 | F26: 秦皇岛 | G26: 华北 | H26: 500798 | I26: 中国 | J26: (089) 3877310 | K26: (089) 3877451
A27: FRANR | B27: 国银贸易 | C27: 余小姐 | D27: 市场经理 | E27: 辅城街 42 号 | F27: 南京 | G27: 华东 | H27: 546590 | I27: 中国 | J27: (087) 40322121 | K27: (087) 40322120
A28: FRANS | B28: 文成 | C28: 唐小姐 | D28: 销售代表 | E28: 临江街 32 号 | F28: 常州 | G28: 华东 | H28: 820097 | I28: 中国 | J28: (056) 34988260 | K28: (056) 34988261
A29: FURIB | B29: 康浦 | C29: 王先生 | D29: 销售经理 | E29: 授业路 361 号 | F29: 南京 | G29: 华东 | H29: 964532 | I29: 中国 | J29: (087) 43542534 | K29: (087) 43542535
A30: GALED | B30: 东旗 | C30: 王先生 | D30: 市场经理 | E30: 尊石路 238 号 | F30: 深圳 | G30: 华南 | H30: 411012 | I30: 中国 | J30: (0571) 20334560 | K30: (0571) 20334561
A31: GODOS | B31: 建资 | C31: 陈先生 | D31: 销售经理 | E31: 广惠东路 38 号 | F31: 张家口 | G31: 华北 | H31: 242353 | I31: 中国 | J31: (0922) 5558282
A32: GOURL | B32: 业兴 | C32: 李柏麟 | D32: 销售员 | E32: 淮河路 348 号 | F32: 上海 | G32: 华东 | H32: 241008 | I32: 中国 | J32: (021) 85559482
A33: GREAL | B33: 仪和贸易 | C33: 王先生 | D33: 市场经理 | E33: 经三纬四路 18 号 | F33: 北京 | G33: 华北 | H33: 120475 | I33: 中国 | J33: (010) 65557555
A34: GROSR | B34: 光远商贸 | C34: 陈先生 | D34: 物主 | E34: 成川东街 951 号 | F34: 天津 | G34: 华北 | H34: 122096 | I34: 中国 | J34: (030) 32832951 | K34: (030) 32833397
A35: HANAR | B35: 实翼 | C35: 谢小姐 | D35: 结算经理 | E35: 永惠西街 392 号 | F35: 南昌 | G35: 华东 | H35: 674674 | I35: 中国 | J35: (0211) 5550091 | K35: (0211) 5558765
A36: HILAA | B36: 远东开发 | C36: 王先生 | D36: 销售代表 | E36: 崇盛路 82 号 | F36: 深圳 | G36: 华南 | H36: 498045 | I36: 中国 | J36: (0571) 75551340 | K36: (0571) 75551948
A37: HUNGC | B37: 五金机械 | C37: 苏先生 | D37: 销售代表 | E37: 德昌路甲 29 号 | F37: 大连 | G37: 东北 | H37: 564576 | I37: 中国 | J37: (053) 5556874 | K37: (053) 5552376
A38: HUNGO | B38: 师大贸易 | C38: 苏先生 | D38: 销售员 | E38: 黄岗北路 73 号 | F38: 天津 | G38: 华北 | H38: 683045 | I38: 中国 | J38: (030) 29672542 | K38: (030) 29673333
A39: ISLAT | B39: 鑫增贸易 | C39: 周先生 | D39: 市场经理 | E39: 东府大街 31 号 | F39: 西安 | G39: 西北 | H39: 502255 | I39: 中国 | J39: (091) 65558888
A40: KOENE | B40: 永业房屋 | C40: 谢丽秋 | D40: 销售员 | E40: 东园大路 78 号 | F40: 重庆 | G40: 西南 | H40: 101057 | I40: 中国 | J40: (025) 55509876
...

Sheet 查询
A1: 客户ID | B1: 公司名称
A2: CHOPS | B2: =VLOOKUP(A2,数据源!A:B,2,0) -> 浩天旅行社
A3: ERNSH | B3: =VLOOKUP(A3,数据源!A:B,2,0) -> 正人资源
A4: HANAR | B4: =VLOOKUP(A4,数据源!A:B,2,0) -> 实翼
A5: ANTON | B5: =VLOOKUP(A5,数据源!A:B,2,0) -> 坦森行贸易
A6: LAUGB | B6: =VLOOKUP(A6,数据源!A:B,2,0) -> 和福建设
A7: LAZYK | B7: =VLOOKUP(A7,数据源!A:B,2,0) -> 春永建设
A8: LEHMS | B8: =VLOOKUP(A8,数据源!A:B,2,0) -> 幸义房屋
A9: LETSS | B9: =VLOOKUP(A9,数据源!A:B,2,0) -> 兴中保险
A10: LILAS | B10: =VLOOKUP(A10,数据源!A:B,2,0) -> 富泰人寿
A11: LINOD | B11: =VLOOKUP(A11,数据源!A:B,2,0) -> 保信人寿
A12: OTTIK | B12: =VLOOKUP(A12,数据源!A:B,2,0) -> 一诠精密工业
A13: PARIS | B13: =VLOOKUP(A13,数据源!A:B,2,0) -> 立日股份有限公司
... A15: SUPRD | B15: =VLOOKUP(A15,数据源!A:B,2,0) -> 福星制衣厂股份有限公司

Sheet 查询2
A1: 公司名称 | B1: 客户ID
A2: 浩天旅行社 | B2: =INDEX(数据源!A:A,MATCH(查询2!A2,数据源!B:B,0),0) -> CHOPS
A3: 正人资源 | B3: =INDEX(数据源!A:A,MATCH(查询2!A3,数据源!B:B,0),0) -> ERNSH
A4: 实翼 | B4: =INDEX(数据源!A:A,MATCH(查询2!A4,数据源!B:B,0),0) -> HANAR
A5: 坦森行贸易 | B5: =INDEX(数据源!A:A,MATCH(查询2!A5,数据源!B:B,0),0) -> ANTON
A6: 和福建设 | B6: =INDEX(数据源!A:A,MATCH(查询2!A6,数据源!B:B,0),0) -> LAUGB
A7: 春永建设 | B7: =INDEX(数据源!A:A,MATCH(查询2!A7,数据源!B:B,0),0) -> LAZYK
A8: 幸义房屋 | B8: =INDEX(数据源!A:A,MATCH(查询2!A8,数据源!B:B,0),0) -> LEHMS
A9: 兴中保险 | B9: =INDEX(数据源!A:A,MATCH(查询2!A9,数据源!B:B,0),0) -> LETSS
A10: 富泰人寿 | B10: =INDEX(数据源!A:A,MATCH(查询2!A10,数据源!B:B,0),0) -> LILAS
A11: 保信人寿 | B11: =INDEX(数据源!A:A,MATCH(查询2!A11,数据源!B:B,0),0) -> LINOD
A12: 一诠精密工业 | B12: =INDEX(数据源!A:A,MATCH(查询2!A12,数据源!B:B,0),0) -> OTTIK
A13: 立日股份有限公司 | B13: =INDEX(数据源!A:A,MATCH(查询2!A13,数据源!B:B,0),0) -> PARIS
... A15: 福星制衣厂股份有限公司 | B15: =INDEX(数据源!A:A,MATCH(查询2!A15,数据源!B:B,0),0) -> SUPRD

Sheet 单元格引用原理
B1: 1 | C1: 2 | D1: 3 | E1: 4 | F1: 5 | G1: 6 | H1: 7 | I1: 8 | J1: 9
A2: 1 | B2: =$A2*B$1 -> 1 | C2: =$A2*C$1 -> 2 | D2: =$A2*D$1 -> 3 | E2: =$A2*E$1 -> 4 | F2: =$A2*F$1 -> 5 | G2: =$A2*G$1 -> 6 | H2: =$A2*H$1 -> 7 | I2: =$A2*I$1 -> 8 | J2: =$A2*J$1 -> 9
A3: 2 | B3: =$A3*B$1 -> 2 | C3: =$A3*C$1 -> 4 | D3: =$A3*D$1 -> 6 | E3: =$A3*E$1 -> 8 | F3: =$A3*F$1 -> 10 | G3: =$A3*G$1 -> 12 | H3: =$A3*H$1 -> 14 | I3: =$A3*I$1 -> 16 | J3: =$A3*J$1 -> 18
A4: 3 | B4: =$A4*B$1 -> 3 | C4: =$A4*C$1 -> 6 | D4: =$A4*D$1 -> 9 | E4: =$A4*E$1 -> 12 | F4: =$A4*F$1 -> 15 | G4: =$A4*G$1 -> 18 | H4: =$A4*H$1 -> 21 | I4: =$A4*I$1 -> 24 | J4: =$A4*J$1 -> 27
A5: 4 | B5: =$A5*B$1 -> 4 | C5: =$A5*C$1 -> 8 | D5: =$A5*D$1 -> 12 | E5: =$A5*E$1 -> 16 | F5: =$A5*F$1 -> 20 | G5: =$A5*G$1 -> 24 | H5: =$A5*H$1 -> 28 | I5: =$A5*I$1 -> 32 | J5: =$A5*J$1 -> 36
A6: 5 | B6: =$A6*B$1 -> 5 | C6: =$A6*C$1 -> 10 | D6: =$A6*D$1 -> 15 | E6: =$A6*E$1 -> 20 | F6: =$A6*F$1 -> 25 | G6: =$A6*G$1 -> 30 | H6: =$A6*H$1 -> 35 | I6: =$A6*I$1 -> 40 | J6: =$A6*J$1 -> 45
A7: 6 | B7: =$A7*B$1 -> 6 | C7: =$A7*C$1 -> 12 | D7: =$A7*D$1 -> 18 | E7: =$A7*E$1 -> 24 | F7: =$A7*F$1 -> 30 | G7: =$A7*G$1 -> 36 | H7: =$A7*H$1 -> 42 | I7: =$A7*I$1 -> 48 | J7: =$A7*J$1 -> 54
A8: 7 | B8: =$A8*B$1 -> 7 | C8: =$A8*C$1 -> 14 | D8: =$A8*D$1 -> 21 | E8: =$A8*E$1 -> 28 | F8: =$A8*F$1 -> 35 | G8: =$A8*G$1 -> 42 | H8: =$A8*H$1 -> 49 | I8: =$A8*I$1 -> 56 | J8: =$A8*J$1 -> 63
A9: 8 | B9: =$A9*B$1 -> 8 | C9: =$A9*C$1 -> 16 | D9: =$A9*D$1 -> 24 | E9: =$A9*E$1 -> 32 | F9: =$A9*F$1 -> 40 | G9: =$A9*G$1 -> 48 | H9: =$A9*H$1 -> 56 | I9: =$A9*I$1 -> 64 | J9: =$A9*J$1 -> 72
A10: 9 | B10: =$A10*B$1 -> 9 | C10: =$A10*C$1 -> 18 | D10: =$A10*D$1 -> 27 | E10: =$A10*E$1 -> 36 | F10: =$A10*F$1 -> 45 | G10: =$A10*G$1 -> 54 | H10: =$A10*H$1 -> 63 | I10: =$A10*I$1 -> 72 | J10: =$A10*J$1 -> 81

Sheet 返回多列结果
A2: 客户ID | B2: 公司名称 | C2: 地址 | D2: 联系人姓名 | E2: 电话 | F2: 城市
A3: CHOPS | B3: =VLOOKUP($A3,数据源!$A$1:$K$92,MATCH(返回多列结果!B$2,数据源!$A$1:$K$1,0),0) -> 浩天旅行社 | C3: =VLOOKUP($A3,数据源!$A$1:$K$92,MATCH(返回多列结果!C$2,数据源!$A$1:$K$1,0),0) -> 白广路 314 号 | D3: =VLOOKUP($A3,数据源!$A$1:$K$92,MATCH(返回多列结果!D$2,数据源!$A$1:$K$1,0),0) -> 方先生 | E3: =VLOOKUP($A3,数据源!$A$1:$K$92,MATCH(返回多列结果!E$2,数据源!$A$1:$K$1,0),0) -> (030) 30076545 | F3: =VLOOKUP($A3,数据源!$A$1:$K$92,MATCH(返回多列结果!F$2,数据源!$A$1:$K$1,0),0) -> 天津
A4: ERNSH | B4: =VLOOKUP($A4,数据源!$A$1:$K$92,MATCH(返回多列结果!B$2,数据源!$A$1:$K$1,0),0) -> 正人资源 | C4: =VLOOKUP($A4,数据源!$A$1:$K$92,MATCH(返回多列结果!C$2,数据源!$A$1:$K$1,0),0) -> 临江东街 62 号 | D4: =VLOOKUP($A4,数据源!$A$1:$K$92,MATCH(返回多列结果!D$2,数据源!$A$1:$K$1,0),0) -> 谢小姐 | E4: =VLOOKUP($A4,数据源!$A$1:$K$92,MATCH(返回多列结果!E$2,数据源!$A$1:$K$1,0),0) -> (0571) 76753425 | F4: =VLOOKUP($A4,数据源!$A$1:$K$92,MATCH(返回多列结果!F$2,数据源!$A$1:$K$1,0),0) -> 深圳
A5: HANAR | B5: =VLOOKUP($A5,数据源!$A$1:$K$92,MATCH(返回多列结果!B$2,数据源!$A$1:$K$1,0),0) -> 实翼 | C5: =VLOOKUP($A5,数据源!$A$1:$K$92,MATCH(返回多列结果!C$2,数据源!$A$1:$K$1,0),0) -> 永惠西街 392 号 | D5: =VLOOKUP($A5,数据源!$A$1:$K$92,MATCH(返回多列结果!D$2,数据源!$A$1:$K$1,0),0) -> 谢小姐 | E5: =VLOOKUP($A5,数据源!$A$1:$K$92,MATCH(返回多列结果!E$2,数据源!$A$1:$K$1,0),0) -> (0211) 5550091 | F5: =VLOOKUP($A5,数据源!$A$1:$K$92,MATCH(返回多列结果!F$2,数据源!$A$1:$K$1,0),0) -> 南昌
A6: ANTON | B6: =VLOOKUP($A6,数据源!$A$1:$K$92,MATCH(返回多列结果!B$2,数据源!$A$1:$K$1,0),0) -> 坦森行贸易 | C6: =VLOOKUP($A6,数据源!$A$1:$K$92,MATCH(返回多列结果!C$2,数据源!$A$1:$K$1,0),0) -> 黄台北路 780 号 | D6: =VLOOKUP($A6,数据源!$A$1:$K$92,MATCH(返回多列结果!D$2,数据源!$A$1:$K$1,0),0) -> 王炫皓 | E6: =VLOOKUP($A6,数据源!$A$1:$K$92,MATCH(返回多列结果!E$2,数据源!$A$1:$K$1,0),0) -> (0321) 5553932 | F6: =VLOOKUP($A6,数据源!$A$1:$K$92,MATCH(返回多列结果!F$2,数据源!$A$1:$K$1,0),0) -> 石家庄
A7: LAUGB | B7: =VLOOKUP($A7,数据源!$A$1:$K$92,MATCH(返回多列结果!B$2,数据源!$A$1:$K$1,0),0) -> 和福建设 | C7: =VLOOKUP($A7,数据源!$A$1:$K$92,MATCH(返回多列结果!C$2,数据源!$A$1:$K$1,0),0) -> 创业西路 238 号 | D7: =VLOOKUP($A7,数据源!$A$1:$K$92,MATCH(返回多列结果!D$2,数据源!$A$1:$K$1,0),0) -> 刘先生 | E7: =VLOOKUP($A7,数据源!$A$1:$K$92,MATCH(返回多列结果!E$2,数据源!$A$1:$K$1,0),0) -> (030) 15553392 | F7: =VLOOKUP($A7,数据源!$A$1:$K$92,MATCH(返回多列结果!F$2,数据源!$A$1:$K$1,0),0) -> 天津
A8: LAZYK | B8: =VLOOKUP($A8,数据源!$A$1:$K$92,MATCH(返回多列结果!B$2,数据源!$A$1:$K$1,0),0) -> 春永建设 | C8: =VLOOKUP($A8,数据源!$A$1:$K$92,MATCH(返回多列结果!C$2,数据源!$A$1:$K$1,0),0) -> 劳动辅路 395 号 | D8: =VLOOKUP($A8,数据源!$A$1:$K$92,MATCH(返回多列结果!D$2,数据源!$A$1:$K$1,0),0) -> 王先生 | E8: =VLOOKUP($A8,数据源!$A$1:$K$92,MATCH(返回多列结果!E$2,数据源!$A$1:$K$1,0),0) -> (0571) 35557969 | F8: =VLOOKUP($A8,数据源!$A$1:$K$92,MATCH(返回多列结果!F$2,数据源!$A$1:$K$1,0),0) -> 深圳
A9: LEHMS | B9: =VLOOKUP($A9,数据源!$A$1:$K$92,MATCH(返回多列结果!B$2,数据源!$A$1:$K$1,0),0) -> 幸义房屋 | C9: =VLOOKUP($A9,数据源!$A$1:$K$92,MATCH(返回多列结果!C$2,数据源!$A$1:$K$1,0),0) -> 七一路 89 号 | D9: =VLOOKUP($A9,数据源!$A$1:$K$92,MATCH(返回多列结果!D$2,数据源!$A$1:$K$1,0),0) -> 刘先生 | E9: =VLOOKUP($A9,数据源!$A$1:$K$92,MATCH(返回多列结果!E$2,数据源!$A$1:$K$1,0),0) -> (069) 20245984 | F9: =VLOOKUP($A9,数据源!$A$1:$K$92,MATCH(返回多列结果!F$2,数据源!$A$1:$K$1,0),0) -> 南京

Sheet Sheet1
A1: CHOPS | B1: =VLOOKUP($A1,数据源!$A$1:$K$92,MATCH(返回多列结果!B$2,数据源!$A$1:$K$1,0),0) -> 浩天旅行社 | C1: =VLOOKUP($A1,数据源!$A$1:$K$92,MATCH(返回多列结果!C$2,数据源!$A$1:$K$1,0),0) -> 白广路 314 号 | D1: =VLOOKUP($A1,数据源!$A$1:$K$92,MATCH(返回多列结果!D$2,数据源!$A$1:$K$1,0),0) -> 方先生 | E1: =VLOOKUP($A1,数据源!$A$1:$K$92,MATCH(返回多列结果!E$2,数据源!$A$1:$K$1,0),0) -> (030) 30076545 | F1: =VLOOKUP($A1,数据源!$A$1:$K$92,MATCH(返回多列结果!F$2,数据源!$A$1:$K$1,0),0) -> 天津 | G1: 男 | J1: 姓名 | K1: 谢小姐
A2: ERNSH | B2: =VLOOKUP($A2,数据源!$A$1:$K$92,MATCH(返回多列结果!B$2,数据源!$A$1:$K$1,0),0) -> 正人资源 | C2: =VLOOKUP($A2,数据源!$A$1:$K$92,MATCH(返回多列结果!C$2,数据源!$A$1:$K$1,0),0) -> 临江东街 62 号 | D2: =VLOOKUP($A2,数据源!$A$1:$K$92,MATCH(返回多列结果!D$2,数据源!$A$1:$K$1,0),0) -> 谢小姐 | E2: =VLOOKUP($A2,数据源!$A$1:$K$92,MATCH(返回多列结果!E$2,数据源!$A$1:$K$1,0),0) -> (0571) 76753425 | F2: =VLOOKUP($A2,数据源!$A$1:$K$92,MATCH(返回多列结果!F$2,数据源!$A$1:$K$1,0),0) -> 深圳 | G2: 女 | J2: 性别 | K2: =VLOOKUP(K1,D1:G3,4) -> 女
A3: HANAR | B3: =VLOOKUP($A3,数据源!$A$1:$K$92,MATCH(返回多列结果!B$2,数据源!$A$1:$K$1,0),0) -> 实翼 | C3: =VLOOKUP($A3,数据源!$A$1:$K$92,MATCH(返回多列结果!C$2,数据源!$A$1:$K$1,0),0) -> 永惠西街 392 号 | D3: =VLOOKUP($A3,数据源!$A$1:$K$92,MATCH(返回多列结果!D$2,数据源!$A$1:$K$1,0),0) -> 谢小姐 | E3: =VLOOKUP($A3,数据源!$A$1:$K$92,MATCH(返回多列结果!E$2,数据源!$A$1:$K$1,0),0) -> (0211) 5550091 | F3: =VLOOKUP($A3,数据源!$A$1:$K$92,MATCH(返回多列结果!F$2,数据源!$A$1:$K$1,0),0) -> 南昌 | G3: 女 | J3: 图片 | K3: =VLOOKUP(K1,D1:H3,5) -> 0

Sheet 返回多列结果2
D3: 客户ID | E3: 公司名称 | F3: 联系人姓名 | G3: 联系人头衔 | H3: 地址 | I3: 城市 | J3: 地区
D4: CHOPS | E4: =VLOOKUP($D4,数据源!$A$1:$K$92,COLUMN()-3,0) -> 浩天旅行社 | F4: =VLOOKUP($D4,数据源!$A$1:$K$92,COLUMN()-3,0) -> 方先生 | G4: =VLOOKUP($D4,数据源!$A$1:$K$92,COLUMN()-3,0) -> 物主 | H4: =VLOOKUP($D4,数据源!$A$1:$K$92,COLUMN()-3,0) -> 白广路 314 号 | I4: =VLOOKUP($D4,数据源!$A$1:$K$92,COLUMN()-3,0) -> 天津 | J4: =VLOOKUP($D4,数据源!$A$1:$K$92,COLUMN()-3,0) -> 华北
D5: ERNSH | E5: =VLOOKUP($D5,数据源!$A$1:$K$92,COLUMN()-3,0) -> 正人资源 | F5: =VLOOKUP($D5,数据源!$A$1:$K$92,COLUMN()-3,0) -> 谢小姐 | G5: =VLOOKUP($D5,数据源!$A$1:$K$92,COLUMN()-3,0) -> 销售经理 | H5: =VLOOKUP($D5,数据源!$A$1:$K$92,COLUMN()-3,0) -> 临江东街 62 号 | I5: =VLOOKUP($D5,数据源!$A$1:$K$92,COLUMN()-3,0) -> 深圳 | J5: =VLOOKUP($D5,数据源!$A$1:$K$92,COLUMN()-3,0) -> 华南
D6: HANAR | E6: =VLOOKUP($D6,数据源!$A$1:$K$92,COLUMN()-3,0) -> 实翼 | F6: =VLOOKUP($D6,数据源!$A$1:$K$92,COLUMN()-3,0) -> 谢小姐 | G6: =VLOOKUP($D6,数据源!$A$1:$K$92,COLUMN()-3,0) -> 结算经理 | H6: =VLOOKUP($D6,数据源!$A$1:$K$92,COLUMN()-3,0) -> 永惠西街 392 号 | I6: =VLOOKUP($D6,数据源!$A$1:$K$92,COLUMN()-3,0) -> 南昌 | J6: =VLOOKUP($D6,数据源!$A$1:$K$92,COLUMN()-3,0) -> 华东
D7: ANTON | E7: =VLOOKUP($D7,数据源!$A$1:$K$92,COLUMN()-3,0) -> 坦森行贸易 | F7: =VLOOKUP($D7,数据源!$A$1:$K$92,COLUMN()-3,0) -> 王炫皓 | G7: =VLOOKUP($D7,数据源!$A$1:$K$92,COLUMN()-3,0) -> 物主 | H7: =VLOOKUP($D7,数据源!$A$1:$K$92,COLUMN()-3,0) -> 黄台北路 780 号 | I7: =VLOOKUP($D7,数据源!$A$1:$K$92,COLUMN()-3,0) -> 石家庄 | J7: =VLOOKUP($D7,数据源!$A$1:$K$92,COLUMN()-3,0) -> 华北
D8: LAUGB | E8: =VLOOKUP($D8,数据源!$A$1:$K$92,COLUMN()-3,0) -> 和福建设 | F8: =VLOOKUP($D8,数据源!$A$1:$K$92,COLUMN()-3,0) -> 刘先生 | G8: =VLOOKUP($D8,数据源!$A$1:$K$92,COLUMN()-3,0) -> 市场助理 | H8: =VLOOKUP($D8,数据源!$A$1:$K$92,COLUMN()-3,0) -> 创业西路 238 号 | I8: =VLOOKUP($D8,数据源!$A$1:$K$92,COLUMN()-3,0) -> 天津 | J8: =VLOOKUP($D8,数据源!$A$1:$K$92,COLUMN()-3,0) -> 华北
D9: LAZYK | E9: =VLOOKUP($D9,数据源!$A$1:$K$92,COLUMN()-3,0) -> 春永建设 | F9: =VLOOKUP($D9,数据源!$A$1:$K$92,COLUMN()-3,0) -> 王先生 | G9: =VLOOKUP($D9,数据源!$A$1:$K$92,COLUMN()-3,0) -> 市场经理 | H9: =VLOOKUP($D9,数据源!$A$1:$K$92,COLUMN()-3,0) -> 劳动辅路 395 号 | I9: =VLOOKUP($D9,数据源!$A$1:$K$92,COLUMN()-3,0) -> 深圳 | J9: =VLOOKUP($D9,数据源!$A$1:$K$92,COLUMN()-3,0) -> 华南
D10: LEHMS | E10: =VLOOKUP($D10,数据源!$A$1:$K$92,COLUMN()-3,0) -> 幸义房屋 | F10: =VLOOKUP($D10,数据源!$A$1:$K$92,COLUMN()-3,0) -> 刘先生 | G10: =VLOOKUP($D10,数据源!$A$1:$K$92,COLUMN()-3,0) -> 销售代表 | H10: =VLOOKUP($D10,数据源!$A$1:$K$92,COLUMN()-3,0) -> 七一路 89 号 | I10: =VLOOKUP($D10,数据源!$A$1:$K$92,COLUMN()-3,0) -> 南京 | J10: =VLOOKUP($D10,数据源!$A$1:$K$92,COLUMN()-3,0) -> 华东
